Workbook

Sheet Policy
A1: ADONI TECH — ImpactCal global price list & costing
A2: Prepared | B2: 2026-09-24
A4: PRICING POLICY (agreed 23-24 Sep 2026)
A5: File prices | B5: Highest price found in any of the 8 uploaded price lists is taken as-is (list price).
A6: Estimated prices | B6: Cost model per series (price ~ k · Fs^a · stroke^b fitted on your own prices; median error 6 % crane, 9 % industrial) + negotiation margin below
A7: Rubber mounts | B7: Moulding cost + hardware + mould cost amortised, + margin over cost (parameters below; Rubber mounts sheet recalculates live)
A8: Rounding | B8: nearest ₹50 below ₹10,000, nearest ₹100 above (always up)
A9: USD | B9: list ÷ live INR/USD rate × (1 + export uplift); recomputed at quotation time; column here is indicative
A11: PARAMETERS (yellow cells are yours to change) | B11: Value | C11: Unit
A12: Negotiation / dealer margin on estimated prices | B12: 25 | C12: %
A13: Dealer price = list × (1 − discount) | B13: 20 | C13: %
A14: INR per USD (indicative) | B14: 95.87 | C14: INR
A15: Export uplift | B15: 12 | C15: %
A16: Rubber compound | B16: 420 | C16: ₹/kg
A17: Rubber density | B17: 1.15 | C17: g/cm³
A18: Moulding cost per shot | B18: 180 | C18: ₹
A19: Moulding cost per kg rubber | B19: 260 | C19: ₹/kg
A20: Metal parts material | B20: 95 | C20: ₹/kg
A21: Metal parts machining / plating | B21: 140 | C21: ₹/kg
A22: Minimum hardware per piece | B22: 35 | C22: ₹
A23: Mould cost — small (Ø ≤ 80) | B23: 28000 | C23: ₹
... A25: Mould cost — large | B25: 80000 | C25: ₹
A26: Cavities per mould — small / medium / large | B26: 8 / 4 / 1
A27: Mould amortised over | B27: 50 | C27: pcs
A28: Margin over cost (rubber mounts) | B28: 50 | C28: %

Sheet Summary
A1: Table | B1: Rows | C1: From price lists | D1: Estimated (model) | E1: Costed (rubber) | F1: Min list ₹ | G1: Max list ₹
A2: accessories | B2: 17 | C2: 0 | D2: 14 | E2: 0 | F2: 0 | G2: 8150
A3: other_products | B3: 14 | C3: 14 | D3: 0 | E3: 0 | F3: 450 | G3: 69400
A4: rubber_mounts | B4: 103 | C4: 1 | D4: 5 | E4: 97 | F4: 500 | G4: 70600
A5: shock_absorbers | B5: 311 | C5: 148 | D5: 163 | E5: 0 | F5: 750 | G5: 141100
A6: wire_rope_isolators | B6: 114 | C6: 114 | D6: 0 | E6: 0 | F6: 1150 | G6: 58000
A8: Legend | B8: yellow = your input (list price / geometry) | C8: blue = estimated value

Sheet Shock absorbers
A1: key | B1: model | C1: series | D1: basis | E1: file_price | F1: file_source | G1: estimate | H1: margin_pct | I1: list_inr | J1: dealer_inr | K1: usd_indicative | L1: lead_time_days | M1: note
A2: AC86 | B2: AC-8-6 | C2: AC | D2: file | E2: 1680 | F2: product_list:market | G2: 1680 | H2: 0 | I2: 1700 | J2: =IF(I2>0,CEILING(I2*(1-Policy!$B$13/100),IF(I2<10000,50,100)),"") | K2: =IF(I2>0,ROUNDUP(I2/Policy!$B$14*(1+Policy!$B$15/100),0),"") | L2: 21 | M2: stroke 6 mm, Fs 417 N
A3: AC105 | B3: AC-10-5 | C3: AC | D3: file | E3: 1440 | F3: product_list:b2b | G3: 1441 | H3: 0 | I3: 1450 | J3: =IF(I3>0,CEILING(I3*(1-Policy!$B$13/100),IF(I3<10000,50,100)),"") | K3: =IF(I3>0,ROUNDUP(I3/Policy!$B$14*(1+Policy!$B$15/100),0),"") | L3: 21 | M3: stroke 5 mm, Fs 750 N
A4: AC108 | B4: AC-10-8 | C4: AC | D4: file | E4: 1500 | F4: product_list:market | G4: 1499 | H4: 0 | I4: 1500 | J4: =IF(I4>0,CEILING(I4*(1-Policy!$B$13/100),IF(I4<10000,50,100)),"") | K4: =IF(I4>0,ROUNDUP(I4/Policy!$B$14*(1+Policy!$B$15/100),0),"") | L4: 21 | M4: stroke 8 mm, Fs 625 N
A5: AC1210 | B5: AC-12-10 | C5: AC | D5: file | E5: 1320 | F5: product_list:b2b | G5: 1320 | H5: 0 | I5: 1350 | J5: =IF(I5>0,CEILING(I5*(1-Policy!$B$13/100),IF(I5<10000,50,100)),"") | K5: =IF(I5>0,ROUNDUP(I5/Policy!$B$14*(1+Policy!$B$15/100),0),"") | L5: 21 | M5: stroke 10 mm, Fs 625 N
A6: AC1410 | B6: AC-14-10 | C6: AC | D6: file | E6: 1100 | F6: price list 2019 (Price List India 2022-23.pdf) | G6: 893 | H6: 0 | I6: 1100 | J6: =IF(I6>0,CEILING(I6*(1-Policy!$B$13/100),IF(I6<10000,50,100)),"") | K6: =IF(I6>0,ROUNDUP(I6/Policy!$B$14*(1+Policy!$B$15/100),0),"") | L6: 21 | M6: stroke 10 mm, Fs 625 N
A7: AC1412 | B7: AC-14-12 | C7: AC | D7: file | E7: 1320 | F7: product_list:b2b | G7: 1463 | H7: 0 | I7: 1350 | J7: =IF(I7>0,CEILING(I7*(1-Policy!$B$13/100),IF(I7<10000,50,100)),"") | K7: =IF(I7>0,ROUNDUP(I7/Policy!$B$14*(1+Policy!$B$15/100),0),"") | L7: 21 | M7: stroke 12 mm, Fs 1562 N
A8: AC1613 | B8: AC-16-13 | C8: AC | D8: file | E8: 1800 | F8: product_list:market | G8: 1800 | H8: 0 | I8: 1800 | J8: =IF(I8>0,CEILING(I8*(1-Policy!$B$13/100),IF(I8<10000,50,100)),"") | K8: =IF(I8>0,ROUNDUP(I8/Policy!$B$14*(1+Policy!$B$15/100),0),"") | L8: 21 | M8: stroke 13 mm, Fs 1635 N
A9: AC2020 | B9: AC-20-20 | C9: AC | D9: file | E9: 3456 | F9: product_list:b2b | G9: 2917 | H9: 0 | I9: 3500 | J9: =IF(I9>0,CEILING(I9*(1-Policy!$B$13/100),IF(I9<10000,50,100)),"") | K9: =IF(I9>0,ROUNDUP(I9/Policy!$B$14*(1+Policy!$B$15/100),0),"") | L9: 21 | M9: stroke 20 mm, Fs 1562 N
A10: AC2220 | B10: AC-22-20 | C10: AC | D10: file | E10: 2765 | F10: product_list:market | G10: 2765 | H10: 0 | I10: 2800 | J10: =IF(I10>0,CEILING(I10*(1-Policy!$B$13/100),IF(I10<10000,50,100)),"") | K10: =IF(I10>0,ROUNDUP(I10/Policy!$B$14*(1+Policy!$B$15/100),0),"") | L10: 21 | M10: stroke 20 mm, Fs 1562 N
A11: AC2050 | B11: AC-20-50 | C11: AC | D11: model | G11: 3669 | H11: 25 | I11: 4600 | J11: =IF(I11>0,CEILING(I11*(1-Policy!$B$13/100),IF(I11<10000,50,100)),"") | K11: =IF(I11>0,ROUNDUP(I11/Policy!$B$14*(1+Policy!$B$15/100),0),"") | L11: 21 | M11: stroke 50 mm, Fs 1500 N
A12: AC2525 | B12: AC-25-25 | C12: AC | D12: file | E12: 4300 | F12: product_list:market | G12: 4624 | H12: 0 | I12: 4300 | J12: =IF(I12>0,CEILING(I12*(1-Policy!$B$13/100),IF(I12<10000,50,100)),"") | K12: =IF(I12>0,ROUNDUP(I12/Policy!$B$14*(1+Policy!$B$15/100),0),"") | L12: 21 | M12: stroke 25 mm, Fs 4250 N
A13: AC2625 | B13: AC-26-25 | C13: AC | D13: file | E13: 4700 | F13: product_list:b2b | G13: 4700 | H13: 0 | I13: 4700 | J13: =IF(I13>0,CEILING(I13*(1-Policy!$B$13/100),IF(I13<10000,50,100)),"") | K13: =IF(I13>0,ROUNDUP(I13/Policy!$B$14*(1+Policy!$B$15/100),0),"") | L13: 21 | M13: stroke 25 mm, Fs 4250 N
A14: AC3025 | B14: AC-30-25 | C14: AC | D14: file | E14: 4600 | F14: product_list:market | G14: 4412 | H14: 0 | I14: 4600 | J14: =IF(I14>0,CEILING(I14*(1-Policy!$B$13/100),IF(I14<10000,50,100)),"") | K14: =IF(I14>0,ROUNDUP(I14/Policy!$B$14*(1+Policy!$B$15/100),0),"") | L14: 21 | M14: stroke 25 mm, Fs 6000 N
A15: AC3325 | B15: AC-33-25 | C15: AC | D15: file | E15: 5000 | F15: product_list:market | G15: 4612 | H15: 0 | I15: 5000 | J15: =IF(I15>0,CEILING(I15*(1-Policy!$B$13/100),IF(I15<10000,50,100)),"") | K15: =IF(I15>0,ROUNDUP(I15/Policy!$B$14*(1+Policy!$B$15/100),0),"") | L15: 21 | M15: stroke 25 mm, Fs 6000 N
A16: AC3625 | B16: AC-36-25 | C16: AC | D16: file | E16: 4800 | F16: product_list:market | G16: 4877 | H16: 0 | I16: 4800 | J16: =IF(I16>0,CEILING(I16*(1-Policy!$B$13/100),IF(I16<10000,50,100)),"") | K16: =IF(I16>0,ROUNDUP(I16/Policy!$B$14*(1+Policy!$B$15/100),0),"") | L16: 21 | M16: stroke 25 mm, Fs 6000 N
A17: AC3725 | B17: AC-37-25 | C17: AC | D17: file | E17: 5200 | F17: product_list:market | G17: 5200 | H17: 0 | I17: 5200 | J17: =IF(I17>0,CEILING(I17*(1-Policy!$B$13/100),IF(I17<10000,50,100)),"") | K17: =IF(I17>0,ROUNDUP(I17/Policy!$B$14*(1+Policy!$B$15/100),0),"") | L17: 21 | M17: stroke 25 mm, Fs 6000 N
A18: AC2540 | B18: AC-25-40 | C18: AC | D18: file | E18: 5500 | F18: product_list:market | G18: 5140 | H18: 0 | I18: 5500 | J18: =IF(I18>0,CEILING(I18*(1-Policy!$B$13/100),IF(I18<10000,50,100)),"") | K18: =IF(I18>0,ROUNDUP(I18/Policy!$B$14*(1+Policy!$B$15/100),0),"") | L18: 21 | M18: stroke 40 mm, Fs 4062 N
A19: AC4225 | B19: AC-42-25 | C19: AC | D19: file | E19: 6600 | F19: product_list:b2b | G19: 6600 | H19: 0 | I19: 6600 | J19: =IF(I19>0,CEILING(I19*(1-Policy!$B$13/100),IF(I19<10000,50,100)),"") | K19: =IF(I19>0,ROUNDUP(I19/Policy!$B$14*(1+Policy!$B$15/100),0),"") | L19: 21 | M19: stroke 25 mm, Fs 12500 N
A20: AC3050 | B20: AC-30-50 | C20: AC | D20: file | E20: 5200 | F20: product_list:market | G20: 5432 | H20: 0 | I20: 5200 | J20: =IF(I20>0,CEILING(I20*(1-Policy!$B$13/100),IF(I20<10000,50,100)),"") | K20: =IF(I20>0,ROUNDUP(I20/Policy!$B$14*(1+Policy!$B$15/100),0),"") | L20: 21 | M20: stroke 50 mm, Fs 6250 N
A21: AC3350 | B21: AC-33-50 | C21: AC | D21: file | E21: 5200 | F21: product_list:b2b | G21: 5678 | H21: 0 | I21: 5200 | J21: =IF(I21>0,CEILING(I21*(1-Policy!$B$13/100),IF(I21<10000,50,100)),"") | K21: =IF(I21>0,ROUNDUP(I21/Policy!$B$14*(1+Policy!$B$15/100),0),"") | L21: 21 | M21: stroke 50 mm, Fs 6250 N
A22: AC3650 | B22: AC-36-50 | C22: AC | D22: file | E22: 6100 | F22: product_list:b2b | G22: 6005 | H22: 0 | I22: 6100 | J22: =IF(I22>0,CEILING(I22*(1-Policy!$B$13/100),IF(I22<10000,50,100)),"") | K22: =IF(I22>0,ROUNDUP(I22/Policy!$B$14*(1+Policy!$B$15/100),0),"") | L22: 21 | M22: stroke 50 mm, Fs 6250 N
A23: AC3750 | B23: AC-37-50 | C23: AC | D23: file | E23: 6600 | F23: product_list:market | G23: 6402 | H23: 0 | I23: 6600 | J23: =IF(I23>0,CEILING(I23*(1-Policy!$B$13/100),IF(I23<10000,50,100)),"") | K23: =IF(I23>0,ROUNDUP(I23/Policy!$B$14*(1+Policy!$B$15/100),0),"") | L23: 21 | M23: stroke 50 mm, Fs 6250 N
... A28: AC64100 | B28: AC-64-100 | C28: AC | D28: file | E28: 12500 | F28: additional models 2018 (Price List India 2022-23.pdf) | G28: 15556 | H28: 0 | I28: 12500 | J28: =IF(I28>0,CEILING(I28*(1-Policy!$B$13/100),IF(I28<10000,50,100)),"") | K28: =IF(I28>0,ROUNDUP(I28/Policy!$B$14*(1+Policy!$B$15/100),0),"") | L28: 21 | M28: stroke 100 mm, Fs 28750 N
A29: AC85125 | B29: AC-85-125 | C29: AC | D29: model | G29: 22637 | H29: 25 | I29: 28300 | J29: =IF(I29>0,CEILING(I29*(1-Policy!$B$13/100),IF(I29<10000,50,100)),"") | K29: =IF(I29>0,ROUNDUP(I29/Policy!$B$14*(1+Policy!$B$15/100),0),"") | L29: 21 | M29: stroke 125 mm, Fs 55000 N
A30: AC85150 | B30: AC-85-150 | C30: AC | D30: model | G30: 22711 | H30: 25 | I30: 28400 | J30: =IF(I30>0,CEILING(I30*(1-Policy!$B$13/100),IF(I30<10000,50,100)),"") | K30: =IF(I30>0,ROUNDUP(I30/Policy!$B$14*(1+Policy!$B$15/100),0),"") | L30: 21 | M30: stroke 150 mm, Fs 50000 N
A31: AC115150 | B31: AC-115-150 | C31: AC | D31: model | G31: 30472 | H31: 25 | I31: 38100 | J31: =IF(I31>0,CEILING(I31*(1-Policy!$B$13/100),IF(I31<10000,50,100)),"") | K31: =IF(I31>0,ROUNDUP(I31/Policy!$B$14*(1+Policy!$B$15/100),0),"") | L31: 21 | M31: stroke 150 mm, Fs 91667 N
A32: AC115200 | B32: AC-115-200 | C32: AC | D32: model | G32: 32765 | H32: 25 | I32: 41000 | J32: =IF(I32>0,CEILING(I32*(1-Policy!$B$13/100),IF(I32<10000,50,100)),"") | K32: =IF(I32>0,ROUNDUP(I32/Policy!$B$14*(1+Policy!$B$15/100),0),"") | L32: 21 | M32: stroke 200 mm, Fs 90625 N
A33: AC115250 | B33: AC-115-250 | C33: AC | D33: model | G33: 35158 | H33: 25 | I33: 44000 | J33: =IF(I33>0,CEILING(I33*(1-Policy!$B$13/100),IF(I33<10000,50,100)),"") | K33: =IF(I33>0,ROUNDUP(I33/Policy!$B$14*(1+Policy!$B$15/100),0),"") | L33: 21 | M33: stroke 250 mm, Fs 92500 N
A34: ACX3325 | B34: ACX-33-25 | C34: ACX | D34: model | G34: 4638 | H34: 25 | I34: 5800 | J34: =IF(I34>0,CEILING(I34*(1-Policy!$B$13/100),IF(I34<10000,50,100)),"") | K34: =IF(I34>0,ROUNDUP(I34/Policy!$B$14*(1+Policy!$B$15/100),0),"") | L34: 21 | M34: stroke 23 mm, Fs 9783 N
A35: ACX3625 | B35: ACX-36-25 | C35: ACX | D35: model | G35: 4638 | H35: 25 | I35: 5800 | J35: =IF(I35>0,CEILING(I35*(1-Policy!$B$13/100),IF(I35<10000,50,100)),"") | K35: =IF(I35>0,ROUNDUP(I35/Policy!$B$14*(1+Policy!$B$15/100),0),"") | L35: 21 | M35: stroke 23 mm, Fs 9783 N
A36: ACX4525 | B36: ACX-45-25 | C36: ACX | D36: model | G36: 6578 | H36: 25 | I36: 7800 | J36: =IF(I36>0,CEILING(I36*(1-Policy!$B$13/100),IF(I36<10000,50,100)),"") | K36: =IF(I36>0,ROUNDUP(I36/Policy!$B$14*(1+Policy!$B$15/100),0),"") | L36: 21 | M36: stroke 23 mm, Fs 20109 N · capped at the next larger priced model
A37: ACX4550 | B37: ACX-45-50 | C37: ACX | D37: file | E37: 7800 | F37: product_list:market | G37: 7800 | H37: 0 | I37: 7800 | J37: =IF(I37>0,CEILING(I37*(1-Policy!$B$13/100),IF(I37<10000,50,100)),"") | K37: =IF(I37>0,ROUNDUP(I37/Policy!$B$14*(1+Policy!$B$15/100),0),"") | L37: 21 | M37: stroke 50 mm, Fs 18500 N
A38: ACX4575 | B38: ACX-45-75 | C38: ACX | D38: model | G38: 8783 | H38: 25 | I38: 11000 | J38: =IF(I38>0,CEILING(I38*(1-Policy!$B$13/100),IF(I38<10000,50,100)),"") | K38: =IF(I38>0,ROUNDUP(I38/Policy!$B$14*(1+Policy!$B$15/100),0),"") | L38: 21 | M38: stroke 75 mm, Fs 18833 N
A39: ACX6450 | B39: ACX-64-50 | C39: ACX | D39: model | G39: 12227 | H39: 25 | I39: 15300 | J39: =IF(I39>0,CEILING(I39*(1-Policy!$B$13/100),IF(I39<10000,50,100)),"") | K39: =IF(I39>0,ROUNDUP(I39/Policy!$B$14*(1+Policy!$B$15/100),0),"") | L39: 21 | M39: stroke 50 mm, Fs 46750 N
A40: ACX64100 | B40: ACX-64-100 | C40: ACX | D40: model | G40: 14740 | H40: 25 | I40: 18500 | J40: =IF(I40>0,CEILING(I40*(1-Policy!$B$13/100),IF(I40<10000,50,100)),"") | K40: =IF(I40>0,ROUNDUP(I40/Policy!$B$14*(1+Policy!$B$15/100),0),"") | L40: 21 | M40: stroke 100 mm, Fs 46625 N
A41: ACX64150 | B41: ACX-64-150 | C41: ACX | D41: model | G41: 16533 | H41: 25 | I41: 20700 | J41: =IF(I41>0,CEILING(I41*(1-Policy!$B$13/100),IF(I41<10000,50,100)),"") | K41: =IF(I41>0,ROUNDUP(I41/Policy!$B$14*(1+Policy!$B$15/100),0),"") | L41: 21 | M41: stroke 150 mm, Fs 47083 N
A42: AD1410 | B42: AD 14-10 | C42: AD | D42: file | E42: 1400 | F42: price list 2019 (Price List India 2022-23.pdf) | G42: 1300 | H42: 0 | I42: 1400 | J42: =IF(I42>0,CEILING(I42*(1-Policy!$B$13/100),IF(I42<10000,50,100)),"") | K42: =IF(I42>0,ROUNDUP(I42/Policy!$B$14*(1+Policy!$B$15/100),0),"") | L42: 28 | M42: stroke 10 mm, Fs 625 N
A43: AD1613 | B43: AD 16-13 | C43: AD | D43: file | E43: 2400 | F43: price list 2019 (Price List India 2022-23.pdf) | G43: 2200 | H43: 0 | I43: 2400 | J43: =IF(I43>0,CEILING(I43*(1-Policy!$B$13/100),IF(I43<10000,50,100)),"") | K43: =IF(I43>0,ROUNDUP(I43/Policy!$B$14*(1+Policy!$B$15/100),0),"") | L43: 28 | M43: stroke 13 mm, Fs 1635 N
A44: AD2020 | B44: AD 20-20 | C44: AD | D44: file | E44: 3600 | F44: product_list:market | G44: 3368 | H44: 0 | I44: 3600 | J44: =IF(I44>0,CEILING(I44*(1-Policy!$B$13/100),IF(I44<10000,50,100)),"") | K44: =IF(I44>0,ROUNDUP(I44/Policy!$B$14*(1+Policy!$B$15/100),0),"") | L44: 28 | M44: stroke 20 mm, Fs 1562 N
...

Sheet Wire rope isolators
A1: key | B1: model | C1: series | D1: basis | E1: file_price | F1: file_source | G1: estimate | H1: margin_pct | I1: list_inr | J1: dealer_inr | K1: usd_indicative | L1: lead_time_days | M1: note
A2: AWRI-16-10 | B2: AWRI-16-10 | C2: AWRI-16 | D2: file | E2: 1800 | F2: product list / AWRI selector | G2: 1479 | H2: 0 | I2: 1800 | J2: =IF(I2>0,CEILING(I2*(1-Policy!$B$13/100),IF(I2<10000,50,100)),"") | K2: =IF(I2>0,ROUNDUP(I2/Policy!$B$14*(1+Policy!$B$15/100),0),"") | L2: 21 | M2: 18x25 mm
A3: AWRI-16-20 | B3: AWRI-16-20 | C3: AWRI-16 | D3: file | E3: 1850 | F3: product list / AWRI selector | G3: 1530 | H3: 0 | I3: 1850 | J3: =IF(I3>0,CEILING(I3*(1-Policy!$B$13/100),IF(I3<10000,50,100)),"") | K3: =IF(I3>0,ROUNDUP(I3/Policy!$B$14*(1+Policy!$B$15/100),0),"") | L3: 21 | M3: 20x28 mm
A4: AWRI-16-40 | B4: AWRI-16-40 | C4: AWRI-16 | D4: file | E4: 2000 | F4: product list / AWRI selector | G4: 1602 | H4: 0 | I4: 2000 | J4: =IF(I4>0,CEILING(I4*(1-Policy!$B$13/100),IF(I4<10000,50,100)),"") | K4: =IF(I4>0,ROUNDUP(I4/Policy!$B$14*(1+Policy!$B$15/100),0),"") | L4: 21 | M4: 25x30 mm
A5: AWRI-16-60 | B5: AWRI-16-60 | C5: AWRI-16 | D5: file | E5: 2050 | F5: product list / AWRI selector | G5: 1655 | H5: 0 | I5: 2050 | J5: =IF(I5>0,CEILING(I5*(1-Policy!$B$13/100),IF(I5<10000,50,100)),"") | K5: =IF(I5>0,ROUNDUP(I5/Policy!$B$14*(1+Policy!$B$15/100),0),"") | L5: 21 | M5: 28x33 mm
A6: AWRI-16-80 | B6: AWRI-16-80 | C6: AWRI-16 | D6: file | E6: 2100 | F6: product list / AWRI selector | G6: 1696 | H6: 0 | I6: 2100 | J6: =IF(I6>0,CEILING(I6*(1-Policy!$B$13/100),IF(I6<10000,50,100)),"") | K6: =IF(I6>0,ROUNDUP(I6/Policy!$B$14*(1+Policy!$B$15/100),0),"") | L6: 21 | M6: 30x36 mm
A7: AWRI-16-71 | B7: AWRI-16-71 | C7: AWRI-16 | D7: file | E7: 2150 | F7: product list / AWRI selector | G7: 1736 | H7: 0 | I7: 2150 | J7: =IF(I7>0,CEILING(I7*(1-Policy!$B$13/100),IF(I7<10000,50,100)),"") | K7: =IF(I7>0,ROUNDUP(I7/Policy!$B$14*(1+Policy!$B$15/100),0),"") | L7: 21 | M7: 33x38 mm
A8: AWRI-24-10 | B8: AWRI-24-10 | C8: AWRI-24 | D8: file | E8: 2150 | F8: product list / AWRI selector | G8: 2186 | H8: 0 | I8: 2150 | J8: =IF(I8>0,CEILING(I8*(1-Policy!$B$13/100),IF(I8<10000,50,100)),"") | K8: =IF(I8>0,ROUNDUP(I8/Policy!$B$14*(1+Policy!$B$15/100),0),"") | L8: 21 | M8: 23x28 mm
A9: AWRI-24-20 | B9: AWRI-24-20 | C9: AWRI-24 | D9: file | E9: 2300 | F9: product list / AWRI selector | G9: 2239 | H9: 0 | I9: 2300 | J9: =IF(I9>0,CEILING(I9*(1-Policy!$B$13/100),IF(I9<10000,50,100)),"") | K9: =IF(I9>0,ROUNDUP(I9/Policy!$B$14*(1+Policy!$B$15/100),0),"") | L9: 21 | M9: 25x30 mm
A10: AWRI-24-40 | B10: AWRI-24-40 | C10: AWRI-24 | D10: file | E10: 2400 | F10: product list / AWRI selector | G10: 2313 | H10: 0 | I10: 2400 | J10: =IF(I10>0,CEILING(I10*(1-Policy!$B$13/100),IF(I10<10000,50,100)),"") | K10: =IF(I10>0,ROUNDUP(I10/Policy!$B$14*(1+Policy!$B$15/100),0),"") | L10: 21 | M10: 28x33 mm
A11: AWRI-24-60 | B11: AWRI-24-60 | C11: AWRI-24 | D11: file | E11: 2500 | F11: product list / AWRI selector | G11: 2426 | H11: 0 | I11: 2500 | J11: =IF(I11>0,CEILING(I11*(1-Policy!$B$13/100),IF(I11<10000,50,100)),"") | K11: =IF(I11>0,ROUNDUP(I11/Policy!$B$14*(1+Policy!$B$15/100),0),"") | L11: 21 | M11: 33x38 mm
A12: AWRI-24-70 | B12: AWRI-24-70 | C12: AWRI-24 | D12: file | E12: 2650 | F12: product list / AWRI selector | G12: 2489 | H12: 0 | I12: 2650 | J12: =IF(I12>0,CEILING(I12*(1-Policy!$B$13/100),IF(I12<10000,50,100)),"") | K12: =IF(I12>0,ROUNDUP(I12/Policy!$B$14*(1+Policy!$B$15/100),0),"") | L12: 21 | M12: 36x41 mm
A13: AWRI-24-80 | B13: AWRI-24-80 | C13: AWRI-24 | D13: file | E13: 2750 | F13: product list / AWRI selector | G13: 2529 | H13: 0 | I13: 2750 | J13: =IF(I13>0,CEILING(I13*(1-Policy!$B$13/100),IF(I13<10000,50,100)),"") | K13: =IF(I13>0,ROUNDUP(I13/Policy!$B$14*(1+Policy!$B$15/100),0),"") | L13: 21 | M13: 38x43 mm
... A115: ACWRI-48-40 | B115: ACWRI-48-40 | C115: ACWRI-48 | D115: file | E115: 5700 | F115: product list / AWRI selector | G115: 4641 | H115: 0 | I115: 5700 | J115: =IF(I115>0,CEILING(I115*(1-Policy!$B$13/100),IF(I115<10000,50,100)),"") | K115: =IF(I115>0,ROUNDUP(I115/Policy!$B$14*(1+Policy!$B$15/100),0),"") | L115: 21 | M115: 79x73 mm

Sheet Accessories
A1: key | B1: model | C1: series | D1: basis | E1: file_price | F1: file_source | G1: estimate | H1: margin_pct | I1: list_inr | J1: dealer_inr | K1: usd_indicative | L1: lead_time_days | M1: note
A2: FF | B2: 0 | C2: accessory | D2: model | G2: 1200 | H2: 25 | I2: 1500 | J2: =IF(I2>0,CEILING(I2*(1-Policy!$B$13/100),IF(I2<10000,50,100)),"") | K2: =IF(I2>0,ROUNDUP(I2/Policy!$B$14*(1+Policy!$B$15/100),0),"") | L2: 14 | M2: typical size AC-25..AC-64; SS and reconditioning quoted case by case; NC free
A3: RF | B3: 1 | C3: accessory | D3: model | G3: 1200 | H3: 25 | I3: 1500 | J3: =IF(I3>0,CEILING(I3*(1-Policy!$B$13/100),IF(I3<10000,50,100)),"") | K3: =IF(I3>0,ROUNDUP(I3/Policy!$B$14*(1+Policy!$B$15/100),0),"") | L3: 14 | M3: typical size AC-25..AC-64; SS and reconditioning quoted case by case; NC free
A4: FRF | B4: 2 | C4: accessory | D4: model | G4: 2200 | H4: 25 | I4: 2750 | J4: =IF(I4>0,CEILING(I4*(1-Policy!$B$13/100),IF(I4<10000,50,100)),"") | K4: =IF(I4>0,ROUNDUP(I4/Policy!$B$14*(1+Policy!$B$15/100),0),"") | L4: 14 | M4: typical size AC-25..AC-64; SS and reconditioning quoted case by case; NC free
A5: FM | B5: 3 | C5: accessory | D5: model | G5: 1500 | H5: 25 | I5: 1900 | J5: =IF(I5>0,CEILING(I5*(1-Policy!$B$13/100),IF(I5<10000,50,100)),"") | K5: =IF(I5>0,ROUNDUP(I5/Policy!$B$14*(1+Policy!$B$15/100),0),"") | L5: 14 | M5: typical size AC-25..AC-64; SS and reconditioning quoted case by case; NC free
A6: RFFF | B6: 4 | C6: accessory | D6: model | G6: 2600 | H6: 25 | I6: 3250 | J6: =IF(I6>0,CEILING(I6*(1-Policy!$B$13/100),IF(I6<10000,50,100)),"") | K6: =IF(I6>0,ROUNDUP(I6/Policy!$B$14*(1+Policy!$B$15/100),0),"") | L6: 14 | M6: typical size AC-25..AC-64; SS and reconditioning quoted case by case; NC free
A7: CM | B7: 5 | C7: accessory | D7: model | G7: 1800 | H7: 25 | I7: 2250 | J7: =IF(I7>0,CEILING(I7*(1-Policy!$B$13/100),IF(I7<10000,50,100)),"") | K7: =IF(I7>0,ROUNDUP(I7/Policy!$B$14*(1+Policy!$B$15/100),0),"") | L7: 14 | M7: typical size AC-25..AC-64; SS and reconditioning quoted case by case; NC free
A8: SC | B8: 6 | C8: accessory | D8: model | G8: 450 | H8: 25 | I8: 600 | J8: =IF(I8>0,CEILING(I8*(1-Policy!$B$13/100),IF(I8<10000,50,100)),"") | K8: =IF(I8>0,ROUNDUP(I8/Policy!$B$14*(1+Policy!$B$15/100),0),"") | L8: 14 | M8: typical size AC-25..AC-64; SS and reconditioning quoted case by case; NC free
A9: SLA | B9: 7 | C9: accessory | D9: model | G9: 2400 | H9: 25 | I9: 3000 | J9: =IF(I9>0,CEILING(I9*(1-Policy!$B$13/100),IF(I9<10000,50,100)),"") | K9: =IF(I9>0,ROUNDUP(I9/Policy!$B$14*(1+Policy!$B$15/100),0),"") | L9: 14 | M9: typical size AC-25..AC-64; SS and reconditioning quoted case by case; NC free
A10: BEL | B10: 8 | C10: accessory | D10: model | G10: 900 | H10: 25 | I10: 1150 | J10: =IF(I10>0,CEILING(I10*(1-Policy!$B$13/100),IF(I10<10000,50,100)),"") | K10: =IF(I10>0,ROUNDUP(I10/Policy!$B$14*(1+Policy!$B$15/100),0),"") | L10: 14 | M10: typical size AC-25..AC-64; SS and reconditioning quoted case by case; NC free
A11: LN | B11: 9 | C11: accessory | D11: model | G11: 250 | H11: 25 | I11: 350 | J11: =IF(I11>0,CEILING(I11*(1-Policy!$B$13/100),IF(I11<10000,50,100)),"") | K11: =IF(I11>0,ROUNDUP(I11/Policy!$B$14*(1+Policy!$B$15/100),0),"") | L11: 14 | M11: typical size AC-25..AC-64; SS and reconditioning quoted case by case; NC free
A12: NC | B12: 10 | C12: accessory | D12: on request | G12: 0 | H12: 0 | I12: 0 | J12: =IF(I12>0,CEILING(I12*(1-Policy!$B$13/100),IF(I12<10000,50,100)),"") | K12: =IF(I12>0,ROUNDUP(I12/Policy!$B$14*(1+Policy!$B$15/100),0),"") | L12: 14 | M12: typical size AC-25..AC-64; SS and reconditioning quoted case by case; NC free
A13: PU | B13: 11 | C13: accessory | D13: model | G13: 350 | H13: 25 | I13: 450 | J13: =IF(I13>0,CEILING(I13*(1-Policy!$B$13/100),IF(I13<10000,50,100)),"") | K13: =IF(I13>0,ROUNDUP(I13/Policy!$B$14*(1+Policy!$B$15/100),0),"") | L13: 14 | M13: typical size AC-25..AC-64; SS and reconditioning quoted case by case; NC free
... A18: RECON | B18: 16 | C18: accessory | D18: on request | G18: 0 | H18: 0 | I18: 0 | J18: =IF(I18>0,CEILING(I18*(1-Policy!$B$13/100),IF(I18<10000,50,100)),"") | K18: =IF(I18>0,ROUNDUP(I18/Policy!$B$14*(1+Policy!$B$15/100),0),"") | L18: 14 | M18: typical size AC-25..AC-64; SS and reconditioning quoted case by case; NC free

Sheet Other products
A1: key | B1: model | C1: series | D1: basis | E1: file_price | F1: file_source | G1: estimate | H1: margin_pct | I1: list_inr | J1: dealer_inr | K1: usd_indicative | L1: lead_time_days | M1: note
A2: TSC-15 | B2: Hydraulic feed-rate controller TSC-15 | C2: other | D2: file | E2: 6150 | F2: product list / TSC pdf | G2: 6150 | H2: 0 | I2: 6150 | J2: =IF(I2>0,CEILING(I2*(1-Policy!$B$13/100),IF(I2<10000,50,100)),"") | K2: =IF(I2>0,ROUNDUP(I2/Policy!$B$14*(1+Policy!$B$15/100),0),"") | L2: 21
A3: TSC-25 | B3: Hydraulic feed-rate controller TSC-25, stroke 30 | C3: other | D3: file | E3: 6600 | F3: product list / TSC pdf | G3: 6600 | H3: 0 | I3: 6600 | J3: =IF(I3>0,CEILING(I3*(1-Policy!$B$13/100),IF(I3<10000,50,100)),"") | K3: =IF(I3>0,ROUNDUP(I3/Policy!$B$14*(1+Policy!$B$15/100),0),"") | L3: 21
A4: TSC-50 | B4: Hydraulic feed-rate controller TSC-50, stroke 60 | C4: other | D4: file | E4: 9840 | F4: product list / TSC pdf | G4: 9840 | H4: 0 | I4: 9850 | J4: =IF(I4>0,CEILING(I4*(1-Policy!$B$13/100),IF(I4<10000,50,100)),"") | K4: =IF(I4>0,ROUNDUP(I4/Policy!$B$14*(1+Policy!$B$15/100),0),"") | L4: 21
A5: TSC-75 | B5: Hydraulic feed-rate controller TSC-75, stroke 80 | C5: other | D5: file | E5: 14400 | F5: product list / TSC pdf | G5: 14400 | H5: 0 | I5: 14400 | J5: =IF(I5>0,CEILING(I5*(1-Policy!$B$13/100),IF(I5<10000,50,100)),"") | K5: =IF(I5>0,ROUNDUP(I5/Policy!$B$14*(1+Policy!$B$15/100),0),"") | L5: 21
A6: TSC-100 | B6: Hydraulic feed-rate controller TSC-100, stroke 100 | C6: other | D6: file | E6: 16625 | F6: product list / TSC pdf | G6: 16625 | H6: 0 | I6: 16700 | J6: =IF(I6>0,CEILING(I6*(1-Policy!$B$13/100),IF(I6<10000,50,100)),"") | K6: =IF(I6>0,ROUNDUP(I6/Policy!$B$14*(1+Policy!$B$15/100),0),"") | L6: 21
A7: ACWRI-40-10 | B7: Compact wire rope isolator ACWRI 40-10 | C7: other | D7: file | E7: 3100 | F7: product list / TSC pdf | G7: 3100 | H7: 0 | I7: 3100 | J7: =IF(I7>0,CEILING(I7*(1-Policy!$B$13/100),IF(I7<10000,50,100)),"") | K7: =IF(I7>0,ROUNDUP(I7/Policy!$B$14*(1+Policy!$B$15/100),0),"") | L7: 21
A8: HHSS20 | B8: Half-helical wire rope isolator HHSS20 | C8: other | D8: file | E8: 16500 | F8: product list / TSC pdf | G8: 16500 | H8: 0 | I8: 16500 | J8: =IF(I8>0,CEILING(I8*(1-Policy!$B$13/100),IF(I8<10000,50,100)),"") | K8: =IF(I8>0,ROUNDUP(I8/Policy!$B$14*(1+Policy!$B$15/100),0),"") | L8: 21
A9: VIBSOL-45W | B9: Vibsol 45 W rubber isolator | C9: other | D9: file | E9: 30000 | F9: product list / TSC pdf | G9: 30000 | H9: 0 | I9: 30000 | J9: =IF(I9>0,CEILING(I9*(1-Policy!$B$13/100),IF(I9<10000,50,100)),"") | K9: =IF(I9>0,ROUNDUP(I9/Policy!$B$14*(1+Policy!$B$15/100),0),"") | L9: 21
A10: SH-500 | B10: SH 500 rubber vibration isolator | C10: other | D10: file | E10: 25000 | F10: product list / TSC pdf | G10: 25000 | H10: 0 | I10: 25000 | J10: =IF(I10>0,CEILING(I10*(1-Policy!$B$13/100),IF(I10<10000,50,100)),"") | K10: =IF(I10>0,ROUNDUP(I10/Policy!$B$14*(1+Policy!$B$15/100),0),"") | L10: 21
A11: AVM-530603 | B11: Diamond shaped anti-vibration mount 530603 | C11: other | D11: file | E11: 450 | F11: product list / TSC pdf | G11: 450 | H11: 0 | I11: 450 | J11: =IF(I11>0,CEILING(I11*(1-Policy!$B$13/100),IF(I11<10000,50,100)),"") | K11: =IF(I11>0,ROUNDUP(I11/Policy!$B$14*(1+Policy!$B$15/100),0),"") | L11: 21
A12: AVM-20x15-M8 | B12: Anti-vibration mount, bilateral bolt 20x15 M8 | C12: other | D12: file | E12: 450 | F12: product list / TSC pdf | G12: 450 | H12: 0 | I12: 450 | J12: =IF(I12>0,CEILING(I12*(1-Policy!$B$13/100),IF(I12<10000,50,100)),"") | K12: =IF(I12>0,ROUNDUP(I12/Policy!$B$14*(1+Policy!$B$15/100),0),"") | L12: 21
A13: AVM-12x10-M5 | B13: Anti-vibration mount, bilateral bolt 12x10 M5 | C13: other | D13: file | E13: 450 | F13: product list / TSC pdf | G13: 450 | H13: 0 | I13: 450 | J13: =IF(I13>0,CEILING(I13*(1-Policy!$B$13/100),IF(I13<10000,50,100)),"") | K13: =IF(I13>0,ROUNDUP(I13/Policy!$B$14*(1+Policy!$B$15/100),0),"") | L13: 21
... A15: KP-125-800 | B15: Hydraulic buffer KP 125-800 | C15: other | D15: file | E15: 69400 | F15: product list / TSC pdf | G15: 69400 | H15: 0 | I15: 69400 | J15: =IF(I15>0,CEILING(I15*(1-Policy!$B$13/100),IF(I15<10000,50,100)),"") | K15: =IF(I15>0,ROUNDUP(I15/Policy!$B$14*(1+Policy!$B$15/100),0),"") | L15: 21

Sheet Rubber mounts
A1: key | B1: model | C1: series | D1: load_max_kg | E1: dia_mm | F1: height_mm | G1: length_mm | H1: cavities | I1: rubber_kg | J1: rubber_cost | K1: moulding | L1: metal_kg | M1: hardware | N1: mould_cost | O1: mould_amort | P1: unit_cost | Q1: margin_pct | R1: list_inr | S1: dealer_inr | T1: usd_indicative | U1: basis | V1: note
A2: AT-OVTN10-20 | B2: AT-OVTN10-20 | C2: OVTN rubber-coated anti-impact isolator | D2: 20 | E2: 111 | F2: 76 | G2: 127 | H2: 4 | I2: 0.326 | J2: =ROUND(I2*Policy!$B$16,0) | K2: =ROUND(Policy!$B$18+I2*Policy!$B$19,0) | L2: 0.664 | M2: =ROUND(MAX(Policy!$B$22,L2*(Policy!$B$20+Policy!$B$21)),0) | N2: =IF(E2<=80,Policy!$B$23,IF(E2<=160,Policy!$B$24,Policy!$B$25)) | O2: =ROUND(N2/(Policy!$B$27*MAX(1,H2)),0) | P2: =J2+K2+M2+O2 | Q2: =Policy!$B$28 | R2: =CEILING(P2*(1+Q2/100),IF(P2*(1+Q2/100)<10000,50,100)) | S2: =IF(R2>0,CEILING(R2*(1-Policy!$B$13/100),IF(R2<10000,50,100)),"") | T2: =IF(R2>0,ROUNDUP(R2/Policy!$B$14*(1+Policy!$B$15/100),0),"") | U2: cost | V2: rubber 0.326 kg + moulding + hardware 0.664 kg + mould 45000/50
A3: AT-OVTN10-15 | B3: AT-OVTN10-15 | C3: OVTN rubber-coated anti-impact isolator | D3: 15 | E3: 111 | F3: 76 | G3: 127 | H3: 4 | I3: 0.326 | J3: =ROUND(I3*Policy!$B$16,0) | K3: =ROUND(Policy!$B$18+I3*Policy!$B$19,0) | L3: 0.664 | M3: =ROUND(MAX(Policy!$B$22,L3*(Policy!$B$20+Policy!$B$21)),0) | N3: =IF(E3<=80,Policy!$B$23,IF(E3<=160,Policy!$B$24,Policy!$B$25)) | O3: =ROUND(N3/(Policy!$B$27*MAX(1,H3)),0) | P3: =J3+K3+M3+O3 | Q3: =Policy!$B$28 | R3: =CEILING(P3*(1+Q3/100),IF(P3*(1+Q3/100)<10000,50,100)) | S3: =IF(R3>0,CEILING(R3*(1-Policy!$B$13/100),IF(R3<10000,50,100)),"") | T3: =IF(R3>0,ROUNDUP(R3/Policy!$B$14*(1+Policy!$B$15/100),0),"") | U3: cost | V3: rubber 0.326 kg + moulding + hardware 0.664 kg + mould 45000/50
A4: AT-OVTN10-10 | B4: AT-OVTN10-10 | C4: OVTN rubber-coated anti-impact isolator | D4: 10 | E4: 111 | F4: 76 | G4: 127 | H4: 4 | I4: 0.326 | J4: =ROUND(I4*Policy!$B$16,0) | K4: =ROUND(Policy!$B$18+I4*Policy!$B$19,0) | L4: 0.664 | M4: =ROUND(MAX(Policy!$B$22,L4*(Policy!$B$20+Policy!$B$21)),0) | N4: =IF(E4<=80,Policy!$B$23,IF(E4<=160,Policy!$B$24,Policy!$B$25)) | O4: =ROUND(N4/(Policy!$B$27*MAX(1,H4)),0) | P4: =J4+K4+M4+O4 | Q4: =Policy!$B$28 | R4: =CEILING(P4*(1+Q4/100),IF(P4*(1+Q4/100)<10000,50,100)) | S4: =IF(R4>0,CEILING(R4*(1-Policy!$B$13/100),IF(R4<10000,50,100)),"") | T4: =IF(R4>0,ROUNDUP(R4/Policy!$B$14*(1+Policy!$B$15/100),0),"") | U4: cost | V4: rubber 0.326 kg + moulding + hardware 0.664 kg + mould 45000/50
A5: AT-OVTN20-150 | B5: AT-OVTN20-150 | C5: OVTN rubber-coated anti-impact isolator | D5: 150 | E5: 165 | F5: 140 | G5: 203 | H5: 1 | I5: 1.325 | J5: =ROUND(I5*Policy!$B$16,0) | K5: =ROUND(Policy!$B$18+I5*Policy!$B$19,0) | L5: 1.578 | M5: =ROUND(MAX(Policy!$B$22,L5*(Policy!$B$20+Policy!$B$21)),0) | N5: =IF(E5<=80,Policy!$B$23,IF(E5<=160,Policy!$B$24,Policy!$B$25)) | O5: =ROUND(N5/(Policy!$B$27*MAX(1,H5)),0) | P5: =J5+K5+M5+O5 | Q5: =Policy!$B$28 | R5: =CEILING(P5*(1+Q5/100),IF(P5*(1+Q5/100)<10000,50,100)) | S5: =IF(R5>0,CEILING(R5*(1-Policy!$B$13/100),IF(R5<10000,50,100)),"") | T5: =IF(R5>0,ROUNDUP(R5/Policy!$B$14*(1+Policy!$B$15/100),0),"") | U5: cost | V5: rubber 1.325 kg + moulding + hardware 1.578 kg + mould 80000/50
A6: AT-OVTN20-100 | B6: AT-OVTN20-100 | C6: OVTN rubber-coated anti-impact isolator | D6: 100 | E6: 165 | F6: 140 | G6: 203 | H6: 1 | I6: 1.325 | J6: =ROUND(I6*Policy!$B$16,0) | K6: =ROUND(Policy!$B$18+I6*Policy!$B$19,0) | L6: 1.578 | M6: =ROUND(MAX(Policy!$B$22,L6*(Policy!$B$20+Policy!$B$21)),0) | N6: =IF(E6<=80,Policy!$B$23,IF(E6<=160,Policy!$B$24,Policy!$B$25)) | O6: =ROUND(N6/(Policy!$B$27*MAX(1,H6)),0) | P6: =J6+K6+M6+O6 | Q6: =Policy!$B$28 | R6: =CEILING(P6*(1+Q6/100),IF(P6*(1+Q6/100)<10000,50,100)) | S6: =IF(R6>0,CEILING(R6*(1-Policy!$B$13/100),IF(R6<10000,50,100)),"") | T6: =IF(R6>0,ROUNDUP(R6/Policy!$B$14*(1+Policy!$B$15/100),0),"") | U6: cost | V6: rubber 1.325 kg + moulding + hardware 1.578 kg + mould 80000/50
A7: AT-OVTN20-50 | B7: AT-OVTN20-50 | C7: OVTN rubber-coated anti-impact isolator | D7: 50 | E7: 165 | F7: 140 | G7: 203 | H7: 1 | I7: 1.325 | J7: =ROUND(I7*Policy!$B$16,0) | K7: =ROUND(Policy!$B$18+I7*Policy!$B$19,0) | L7: 1.578 | M7: =ROUND(MAX(Policy!$B$22,L7*(Policy!$B$20+Policy!$B$21)),0) | N7: =IF(E7<=80,Policy!$B$23,IF(E7<=160,Policy!$B$24,Policy!$B$25)) | O7: =ROUND(N7/(Policy!$B$27*MAX(1,H7)),0) | P7: =J7+K7+M7+O7 | Q7: =Policy!$B$28 | R7: =CEILING(P7*(1+Q7/100),IF(P7*(1+Q7/100)<10000,50,100)) | S7: =IF(R7>0,CEILING(R7*(1-Policy!$B$13/100),IF(R7<10000,50,100)),"") | T7: =IF(R7>0,ROUNDUP(R7/Policy!$B$14*(1+Policy!$B$15/100),0),"") | U7: cost | V7: rubber 1.325 kg + moulding + hardware 1.578 kg + mould 80000/50
A8: AT-OVTN30-250 | B8: AT-OVTN30-250 | C8: OVTN rubber-coated anti-impact isolator | D8: 250 | E8: 165 | F8: 140 | G8: 241 | H8: 1 | I8: 1.325 | J8: =ROUND(I8*Policy!$B$16,0) | K8: =ROUND(Policy!$B$18+I8*Policy!$B$19,0) | L8: 1.873 | M8: =ROUND(MAX(Policy!$B$22,L8*(Policy!$B$20+Policy!$B$21)),0) | N8: =IF(E8<=80,Policy!$B$23,IF(E8<=160,Policy!$B$24,Policy!$B$25)) | O8: =ROUND(N8/(Policy!$B$27*MAX(1,H8)),0) | P8: =J8+K8+M8+O8 | Q8: =Policy!$B$28 | R8: =CEILING(P8*(1+Q8/100),IF(P8*(1+Q8/100)<10000,50,100)) | S8: =IF(R8>0,CEILING(R8*(1-Policy!$B$13/100),IF(R8<10000,50,100)),"") | T8: =IF(R8>0,ROUNDUP(R8/Policy!$B$14*(1+Policy!$B$15/100),0),"") | U8: cost | V8: rubber 1.325 kg + moulding + hardware 1.873 kg + mould 80000/50
A9: AT-OVTN30-125 | B9: AT-OVTN30-125 | C9: OVTN rubber-coated anti-impact isolator | D9: 125 | E9: 165 | F9: 140 | G9: 241 | H9: 1 | I9: 1.325 | J9: =ROUND(I9*Policy!$B$16,0) | K9: =ROUND(Policy!$B$18+I9*Policy!$B$19,0) | L9: 1.873 | M9: =ROUND(MAX(Policy!$B$22,L9*(Policy!$B$20+Policy!$B$21)),0) | N9: =IF(E9<=80,Policy!$B$23,IF(E9<=160,Policy!$B$24,Policy!$B$25)) | O9: =ROUND(N9/(Policy!$B$27*MAX(1,H9)),0) | P9: =J9+K9+M9+O9 | Q9: =Policy!$B$28 | R9: =CEILING(P9*(1+Q9/100),IF(P9*(1+Q9/100)<10000,50,100)) | S9: =IF(R9>0,CEILING(R9*(1-Policy!$B$13/100),IF(R9<10000,50,100)),"") | T9: =IF(R9>0,ROUNDUP(R9/Policy!$B$14*(1+Policy!$B$15/100),0),"") | U9: cost | V9: rubber 1.325 kg + moulding + hardware 1.873 kg + mould 80000/50
A10: AT-OVTN30-60 | B10: AT-OVTN30-60 | C10: OVTN rubber-coated anti-impact isolator | D10: 60 | E10: 165 | F10: 140 | G10: 241 | H10: 1 | I10: 1.325 | J10: =ROUND(I10*Policy!$B$16,0) | K10: =ROUND(Policy!$B$18+I10*Policy!$B$19,0) | L10: 1.873 | M10: =ROUND(MAX(Policy!$B$22,L10*(Policy!$B$20+Policy!$B$21)),0) | N10: =IF(E10<=80,Policy!$B$23,IF(E10<=160,Policy!$B$24,Policy!$B$25)) | O10: =ROUND(N10/(Policy!$B$27*MAX(1,H10)),0) | P10: =J10+K10+M10+O10 | Q10: =Policy!$B$28 | R10: =CEILING(P10*(1+Q10/100),IF(P10*(1+Q10/100)<10000,50,100)) | S10: =IF(R10>0,CEILING(R10*(1-Policy!$B$13/100),IF(R10<10000,50,100)),"") | T10: =IF(R10>0,ROUNDUP(R10/Policy!$B$14*(1+Policy!$B$15/100),0),"") | U10: cost | V10: rubber 1.325 kg + moulding + hardware 1.873 kg + mould 80000/50
A11: AT-OVTN40-300 | B11: AT-OVTN40-300 | C11: OVTN rubber-coated anti-impact isolator | D11: 300 | E11: 235 | F11: 165 | G11: 279 | H11: 1 | I11: 3.169 | J11: =ROUND(I11*Policy!$B$16,0) | K11: =ROUND(Policy!$B$18+I11*Policy!$B$19,0) | L11: 3.088 | M11: =ROUND(MAX(Policy!$B$22,L11*(Policy!$B$20+Policy!$B$21)),0) | N11: =IF(E11<=80,Policy!$B$23,IF(E11<=160,Policy!$B$24,Policy!$B$25)) | O11: =ROUND(N11/(Policy!$B$27*MAX(1,H11)),0) | P11: =J11+K11+M11+O11 | Q11: =Policy!$B$28 | R11: =CEILING(P11*(1+Q11/100),IF(P11*(1+Q11/100)<10000,50,100)) | S11: =IF(R11>0,CEILING(R11*(1-Policy!$B$13/100),IF(R11<10000,50,100)),"") | T11: =IF(R11>0,ROUNDUP(R11/Policy!$B$14*(1+Policy!$B$15/100),0),"") | U11: cost | V11: rubber 3.169 kg + moulding + hardware 3.088 kg + mould 80000/50
A12: AT-OVTN40-200 | B12: AT-OVTN40-200 | C12: OVTN rubber-coated anti-impact isolator | D12: 200 | E12: 235 | F12: 165 | G12: 279 | H12: 1 | I12: 3.169 | J12: =ROUND(I12*Policy!$B$16,0) | K12: =ROUND(Policy!$B$18+I12*Policy!$B$19,0) | L12: 3.088 | M12: =ROUND(MAX(Policy!$B$22,L12*(Policy!$B$20+Policy!$B$21)),0) | N12: =IF(E12<=80,Policy!$B$23,IF(E12<=160,Policy!$B$24,Policy!$B$25)) | O12: =ROUND(N12/(Policy!$B$27*MAX(1,H12)),0) | P12: =J12+K12+M12+O12 | Q12: =Policy!$B$28 | R12: =CEILING(P12*(1+Q12/100),IF(P12*(1+Q12/100)<10000,50,100)) | S12: =IF(R12>0,CEILING(R12*(1-Policy!$B$13/100),IF(R12<10000,50,100)),"") | T12: =IF(R12>0,ROUNDUP(R12/Policy!$B$14*(1+Policy!$B$15/100),0),"") | U12: cost | V12: rubber 3.169 kg + moulding + hardware 3.088 kg + mould 80000/50
A13: AT-OVTN40-80 | B13: AT-OVTN40-80 | C13: OVTN rubber-coated anti-impact isolator | D13: 80 | E13: 235 | F13: 165 | G13: 279 | H13: 1 | I13: 3.169 | J13: =ROUND(I13*Policy!$B$16,0) | K13: =ROUND(Policy!$B$18+I13*Policy!$B$19,0) | L13: 3.088 | M13: =ROUND(MAX(Policy!$B$22,L13*(Policy!$B$20+Policy!$B$21)),0) | N13: =IF(E13<=80,Policy!$B$23,IF(E13<=160,Policy!$B$24,Policy!$B$25)) | O13: =ROUND(N13/(Policy!$B$27*MAX(1,H13)),0) | P13: =J13+K13+M13+O13 | Q13: =Policy!$B$28 | R13: =CEILING(P13*(1+Q13/100),IF(P13*(1+Q13/100)<10000,50,100)) | S13: =IF(R13>0,CEILING(R13*(1-Policy!$B$13/100),IF(R13<10000,50,100)),"") | T13: =IF(R13>0,ROUNDUP(R13/Policy!$B$14*(1+Policy!$B$15/100),0),"") | U13: cost | V13: rubber 3.169 kg + moulding + hardware 3.088 kg + mould 80000/50
... A91: AT-6JX-1200 | B91: AT-6JX-1200 | C91: Rubber 6JX shock absorber | D91: 1200 | E91: 193 | F91: 135 | G91: 340 | H91: 1 | I91: 2.498 | J91: =ROUND(I91*Policy!$B$16,0) | K91: =ROUND(Policy!$B$18+I91*Policy!$B$19,0) | L91: 3.091 | M91: =ROUND(MAX(Policy!$B$22,L91*(Policy!$B$20+Policy!$B$21)),0) | N91: =IF(E91<=80,Policy!$B$23,IF(E91<=160,Policy!$B$24,Policy!$B$25)) | O91: =ROUND(N91/(Policy!$B$27*MAX(1,H91)),0) | P91: =J91+K91+M91+O91 | Q91: =Policy!$B$28 | R91: =CEILING(P91*(1+Q91/100),IF(P91*(1+Q91/100)<10000,50,100)) | S91: =IF(R91>0,CEILING(R91*(1-Policy!$B$13/100),IF(R91<10000,50,100)),"") | T91: =IF(R91>0,ROUNDUP(R91/Policy!$B$14*(1+Policy!$B$15/100),0),"") | U91: cost | V91: rubber 2.498 kg + moulding + hardware 3.091 kg + mould 80000/50
A92: AT-SH-500 | B92: AT-SH-500 | C92: Rubber SH isolator | D92: 500 | E92: 90 | F92: 68 | G92: 230 | H92: 4 | I92: 0.274 | J92: =ROUND(I92*Policy!$B$16,0) | K92: =ROUND(Policy!$B$18+I92*Policy!$B$19,0) | L92: 0.975 | M92: =ROUND(MAX(Policy!$B$22,L92*(Policy!$B$20+Policy!$B$21)),0) | N92: =IF(E92<=80,Policy!$B$23,IF(E92<=160,Policy!$B$24,Policy!$B$25)) | O92: =ROUND(N92/(Policy!$B$27*MAX(1,H92)),0) | P92: =J92+K92+M92+O92 | Q92: 0 | R92: 25000 | S92: =IF(R92>0,CEILING(R92*(1-Policy!$B$13/100),IF(R92<10000,50,100)),"") | T92: =IF(R92>0,ROUNDUP(R92/Policy!$B$14*(1+Policy!$B$15/100),0),"") | U92: file | V92: rubber 0.274 kg + moulding + hardware 0.975 kg + mould 45000/50
A93: AT-SH-750 | B93: AT-SH-750 | C93: Rubber SH isolator | D93: 750 | E93: 110 | F93: 68 | G93: 280 | H93: 4 | I93: 0.409 | J93: =ROUND(I93*Policy!$B$16,0) | K93: =ROUND(Policy!$B$18+I93*Policy!$B$19,0) | L93: 1.451 | M93: =ROUND(MAX(Policy!$B$22,L93*(Policy!$B$20+Policy!$B$21)),0) | N93: =IF(E93<=80,Policy!$B$23,IF(E93<=160,Policy!$B$24,Policy!$B$25)) | O93: =ROUND(N93/(Policy!$B$27*MAX(1,H93)),0) | P93: =J93+K93+M93+O93 | Q93: 50 | R93: 33300 | S93: =IF(R93>0,CEILING(R93*(1-Policy!$B$13/100),IF(R93<10000,50,100)),"") | T93: =IF(R93>0,ROUNDUP(R93/Policy!$B$14*(1+Policy!$B$15/100),0),"") | U93: model | V93: scaled from AT-SH-500 by load^0.7
A94: AT-SH-1150 | B94: AT-SH-1150 | C94: Rubber SH isolator | D94: 1150 | H94: 4 | I94: 0.627 | J94: =ROUND(I94*Policy!$B$16,0) | K94: =ROUND(Policy!$B$18+I94*Policy!$B$19,0) | L94: 1.929 | M94: =ROUND(MAX(Policy!$B$22,L94*(Policy!$B$20+Policy!$B$21)),0) | N94: =IF(E94<=80,Policy!$B$23,IF(E94<=160,Policy!$B$24,Policy!$B$25)) | O94: =ROUND(N94/(Policy!$B$27*MAX(1,H94)),0) | P94: =J94+K94+M94+O94 | Q94: 50 | R94: 44800 | S94: =IF(R94>0,CEILING(R94*(1-Policy!$B$13/100),IF(R94<10000,50,100)),"") | T94: =IF(R94>0,ROUNDUP(R94/Policy!$B$14*(1+Policy!$B$15/100),0),"") | U94: model | V94: scaled from AT-SH-500 by load^0.7
A95: AT-SH-1750 | B95: AT-SH-1750 | C95: Rubber SH isolator | D95: 1750 | H95: 4 | I95: 0.954 | J95: =ROUND(I95*Policy!$B$16,0) | K95: =ROUND(Policy!$B$18+I95*Policy!$B$19,0) | L95: 2.552 | M95: =ROUND(MAX(Policy!$B$22,L95*(Policy!$B$20+Policy!$B$21)),0) | N95: =IF(E95<=80,Policy!$B$23,IF(E95<=160,Policy!$B$24,Policy!$B$25)) | O95: =ROUND(N95/(Policy!$B$27*MAX(1,H95)),0) | P95: =J95+K95+M95+O95 | Q95: 50 | R95: 60100 | S95: =IF(R95>0,CEILING(R95*(1-Policy!$B$13/100),IF(R95<10000,50,100)),"") | T95: =IF(R95>0,ROUNDUP(R95/Policy!$B$14*(1+Policy!$B$15/100),0),"") | U95: model | V95: scaled from AT-SH-500 by load^0.7
A96: AT-SH-2200A | B96: AT-SH-2200A | C96: Rubber SH isolator | D96: 2200 | H96: 4 | I96: 1.199 | J96: =ROUND(I96*Policy!$B$16,0) | K96: =ROUND(Policy!$B$18+I96*Policy!$B$19,0) | L96: 2.973 | M96: =ROUND(MAX(Policy!$B$22,L96*(Policy!$B$20+Policy!$B$21)),0) | N96: =IF(E96<=80,Policy!$B$23,IF(E96<=160,Policy!$B$24,Policy!$B$25)) | O96: =ROUND(N96/(Policy!$B$27*MAX(1,H96)),0) | P96: =J96+K96+M96+O96 | Q96: 50 | R96: 70600 | S96: =IF(R96>0,CEILING(R96*(1-Policy!$B$13/100),IF(R96<10000,50,100)),"") | T96: =IF(R96>0,ROUNDUP(R96/Policy!$B$14*(1+Policy!$B$15/100),0),"") | U96: model | V96: scaled from AT-SH-500 by load^0.7
A97: AT-SH-2200B | B97: AT-SH-2200B | C97: Rubber SH isolator | D97: 2200 | H97: 4 | I97: 1.199 | J97: =ROUND(I97*Policy!$B$16,0) | K97: =ROUND(Policy!$B$18+I97*Policy!$B$19,0) | L97: 2.973 | M97: =ROUND(MAX(Policy!$B$22,L97*(Policy!$B$20+Policy!$B$21)),0) | N97: =IF(E97<=80,Policy!$B$23,IF(E97<=160,Policy!$B$24,Policy!$B$25)) | O97: =ROUND(N97/(Policy!$B$27*MAX(1,H97)),0) | P97: =J97+K97+M97+O97 | Q97: 50 | R97: 70600 | S97: =IF(R97>0,CEILING(R97*(1-Policy!$B$13/100),IF(R97<10000,50,100)),"") | T97: =IF(R97>0,ROUNDUP(R97/Policy!$B$14*(1+Policy!$B$15/100),0),"") | U97: model | V97: scaled from AT-SH-500 by load^0.7
A98: AT-WH-150 | B98: AT-WH-150 | C98: Rubber WH/WHG isolator | D98: 152.9 | E98: 127 | F98: 80 | G98: 185 | H98: 4 | I98: 0.641 | J98: =ROUND(I98*Policy!$B$16,0) | K98: =ROUND(Policy!$B$18+I98*Policy!$B$19,0) | L98: 1.107 | M98: =ROUND(MAX(Policy!$B$22,L98*(Policy!$B$20+Policy!$B$21)),0) | N98: =IF(E98<=80,Policy!$B$23,IF(E98<=160,Policy!$B$24,Policy!$B$25)) | O98: =ROUND(N98/(Policy!$B$27*MAX(1,H98)),0) | P98: =J98+K98+M98+O98 | Q98: =Policy!$B$28 | R98: =CEILING(P98*(1+Q98/100),IF(P98*(1+Q98/100)<10000,50,100)) | S98: =IF(R98>0,CEILING(R98*(1-Policy!$B$13/100),IF(R98<10000,50,100)),"") | T98: =IF(R98>0,ROUNDUP(R98/Policy!$B$14*(1+Policy!$B$15/100),0),"") | U98: cost | V98: rubber 0.641 kg + moulding + hardware 1.107 kg + mould 45000/50
A99: AT-WH-250 | B99: AT-WH-250 | C99: Rubber WH/WHG isolator | D99: 254.8 | E99: 127 | F99: 80 | G99: 185 | H99: 4 | I99: 0.641 | J99: =ROUND(I99*Policy!$B$16,0) | K99: =ROUND(Policy!$B$18+I99*Policy!$B$19,0) | L99: 1.107 | M99: =ROUND(MAX(Policy!$B$22,L99*(Policy!$B$20+Policy!$B$21)),0) | N99: =IF(E99<=80,Policy!$B$23,IF(E99<=160,Policy!$B$24,Policy!$B$25)) | O99: =ROUND(N99/(Policy!$B$27*MAX(1,H99)),0) | P99: =J99+K99+M99+O99 | Q99: =Policy!$B$28 | R99: =CEILING(P99*(1+Q99/100),IF(P99*(1+Q99/100)<10000,50,100)) | S99: =IF(R99>0,CEILING(R99*(1-Policy!$B$13/100),IF(R99<10000,50,100)),"") | T99: =IF(R99>0,ROUNDUP(R99/Policy!$B$14*(1+Policy!$B$15/100),0),"") | U99: cost | V99: rubber 0.641 kg + moulding + hardware 1.107 kg + mould 45000/50
A100: AT-WH-400 | B100: AT-WH-400 | C100: Rubber WH/WHG isolator | D100: 407.7 | E100: 127 | F100: 80 | G100: 185 | H100: 4 | I100: 0.641 | J100: =ROUND(I100*Policy!$B$16,0) | K100: =ROUND(Policy!$B$18+I100*Policy!$B$19,0) | L100: 1.107 | M100: =ROUND(MAX(Policy!$B$22,L100*(Policy!$B$20+Policy!$B$21)),0) | N100: =IF(E100<=80,Policy!$B$23,IF(E100<=160,Policy!$B$24,Policy!$B$25)) | O100: =ROUND(N100/(Policy!$B$27*MAX(1,H100)),0) | P100: =J100+K100+M100+O100 | Q100: =Policy!$B$28 | R100: =CEILING(P100*(1+Q100/100),IF(P100*(1+Q100/100)<10000,50,100)) | S100: =IF(R100>0,CEILING(R100*(1-Policy!$B$13/100),IF(R100<10000,50,100)),"") | T100: =IF(R100>0,ROUNDUP(R100/Policy!$B$14*(1+Policy!$B$15/100),0),"") | U100: cost | V100: rubber 0.641 kg + moulding + hardware 1.107 kg + mould 45000/50
A101: AT-WHG-600 | B101: AT-WHG-600 | C101: Rubber WH/WHG isolator | D101: 611.6 | E101: 144 | F101: 100 | G101: 280 | H101: 4 | I101: 1.03 | J101: =ROUND(I101*Policy!$B$16,0) | K101: =ROUND(Policy!$B$18+I101*Policy!$B$19,0) | L101: 1.899 | M101: =ROUND(MAX(Policy!$B$22,L101*(Policy!$B$20+Policy!$B$21)),0) | N101: =IF(E101<=80,Policy!$B$23,IF(E101<=160,Policy!$B$24,Policy!$B$25)) | O101: =ROUND(N101/(Policy!$B$27*MAX(1,H101)),0) | P101: =J101+K101+M101+O101 | Q101: =Policy!$B$28 | R101: =CEILING(P101*(1+Q101/100),IF(P101*(1+Q101/100)<10000,50,100)) | S101: =IF(R101>0,CEILING(R101*(1-Policy!$B$13/100),IF(R101<10000,50,100)),"") | T101: =IF(R101>0,ROUNDUP(R101/Policy!$B$14*(1+Policy!$B$15/100),0),"") | U101: cost | V101: rubber 1.03 kg + moulding + hardware 1.899 kg + mould 45000/50
A102: AT-WHG-800 | B102: AT-WHG-800 | C102: Rubber WH/WHG isolator | D102: 815.5 | E102: 144 | F102: 100 | G102: 334 | H102: 4 | I102: 1.03 | J102: =ROUND(I102*Policy!$B$16,0) | K102: =ROUND(Policy!$B$18+I102*Policy!$B$19,0) | L102: 2.265 | M102: =ROUND(MAX(Policy!$B$22,L102*(Policy!$B$20+Policy!$B$21)),0) | N102: =IF(E102<=80,Policy!$B$23,IF(E102<=160,Policy!$B$24,Policy!$B$25)) | O102: =ROUND(N102/(Policy!$B$27*MAX(1,H102)),0) | P102: =J102+K102+M102+O102 | Q102: =Policy!$B$28 | R102: =CEILING(P102*(1+Q102/100),IF(P102*(1+Q102/100)<10000,50,100)) | S102: =IF(R102>0,CEILING(R102*(1-Policy!$B$13/100),IF(R102<10000,50,100)),"") | T102: =IF(R102>0,ROUNDUP(R102/Policy!$B$14*(1+Policy!$B$15/100),0),"") | U102: cost | V102: rubber 1.03 kg + moulding + hardware 2.265 kg + mould 45000/50
A103: AT-WHG-1200 | B103: AT-WHG-1200 | C103: Rubber WH/WHG isolator | D103: 1223.2 | E103: 204 | F103: 130 | G103: 340 | H103: 1 | I103: 2.688 | J103: =ROUND(I103*Policy!$B$16,0) | K103: =ROUND(Policy!$B$18+I103*Policy!$B$19,0) | L103: 3.267 | M103: =ROUND(MAX(Policy!$B$22,L103*(Policy!$B$20+Policy!$B$21)),0) | N103: =IF(E103<=80,Policy!$B$23,IF(E103<=160,Policy!$B$24,Policy!$B$25)) | O103: =ROUND(N103/(Policy!$B$27*MAX(1,H103)),0) | P103: =J103+K103+M103+O103 | Q103: =Policy!$B$28 | R103: =CEILING(P103*(1+Q103/100),IF(P103*(1+Q103/100)<10000,50,100)) | S103: =IF(R103>0,CEILING(R103*(1-Policy!$B$13/100),IF(R103<10000,50,100)),"") | T103: =IF(R103>0,ROUNDUP(R103/Policy!$B$14*(1+Policy!$B$15/100),0),"") | U103: cost | V103: rubber 2.688 kg + moulding + hardware 3.267 kg + mould 80000/50
A104: AT-WHG-1750 | B104: AT-WHG-1750 | C104: Rubber WH/WHG isolator | D104: 1783.9 | E104: 204 | F104: 130 | G104: 460 | H104: 1 | I104: 2.688 | J104: =ROUND(I104*Policy!$B$16,0) | K104: =ROUND(Policy!$B$18+I104*Policy!$B$19,0) | L104: 4.42 | M104: =ROUND(MAX(Policy!$B$22,L104*(Policy!$B$20+Policy!$B$21)),0) | N104: =IF(E104<=80,Policy!$B$23,IF(E104<=160,Policy!$B$24,Policy!$B$25)) | O104: =ROUND(N104/(Policy!$B$27*MAX(1,H104)),0) | P104: =J104+K104+M104+O104 | Q104: =Policy!$B$28 | R104: =CEILING(P104*(1+Q104/100),IF(P104*(1+Q104/100)<10000,50,100)) | S104: =IF(R104>0,CEILING(R104*(1-Policy!$B$13/100),IF(R104<10000,50,100)),"") | T104: =IF(R104>0,ROUNDUP(R104/Policy!$B$14*(1+Policy!$B$15/100),0),"") | U104: cost | V104: rubber 2.688 kg + moulding + hardware 4.42 kg + mould 80000/50
